Traceback (most recent call last):
  File "/home/runner/LocalLandmarkExplorer/.pythonlibs/lib/python3.11/site-packages/redis/connection.py", line 277, in connect
    sock = self.retry.call_with_retry(
           ^^^^^^^^^^^^^^^^^^^^^^^^^^^
  File "/home/runner/LocalLandmarkExplorer/.pythonlibs/lib/python3.11/site-packages/redis/retry.py", line 62, in call_with_retry
    return do()
           ^^^^
  File "/home/runner/LocalLandmarkExplorer/.pythonlibs/lib/python3.11/site-packages/redis/connection.py", line 278, in <lambda>
    lambda: self._connect(), lambda error: self.disconnect(error)
            ^^^^^^^^^^^^^^^
  File "/home/runner/LocalLandmarkExplorer/.pythonlibs/lib/python3.11/site-packages/redis/connection.py", line 639, in _connect
    raise err
  File "/home/runner/LocalLandmarkExplorer/.pythonlibs/lib/python3.11/site-packages/redis/connection.py", line 627, in _connect
    sock.connect(socket_address)
OSError: [Errno 99] Cannot assign requested address

During handling of the above exception, another exception occurred:

Traceback (most recent call last):
  File "/home/runner/LocalLandmarkExplorer/.pythonlibs/lib/python3.11/site-packages/flask/app.py", line 1473, in wsgi_app
    response = self.full_dispatch_request()
               ^^^^^^^^^^^^^^^^^^^^^^^^^^^^
  File "/home/runner/LocalLandmarkExplorer/.pythonlibs/lib/python3.11/site-packages/flask/app.py", line 882, in full_dispatch_request
    rv = self.handle_user_exception(e)
         ^^^^^^^^^^^^^^^^^^^^^^^^^^^^^
  File "/home/runner/LocalLandmarkExplorer/.pythonlibs/lib/python3.11/site-packages/flask/app.py", line 880, in full_dispatch_request
    rv = self.dispatch_request()
         ^^^^^^^^^^^^^^^^^^^^^^^
  File "/home/runner/LocalLandmarkExplorer/.pythonlibs/lib/python3.11/site-packages/flask/app.py", line 865, in dispatch_request
    return self.ensure_sync(self.view_functions[rule.endpoint])(**view_args)  # type: ignore[no-any-return]
           ^^^^^^^^^^^^^^^^^^^^^^^^^^^^^^^^^^^^^^^^^^^^^^^^^^^^^^^^^^^^^^^^^
  File "/home/runner/LocalLandmarkExplorer/main.py", line 61, in get_landmarks
    cached_data = redis_client.get(cache_key)
                  ^^^^^^^^^^^^^^^^^^^^^^^^^^^
  File "/home/runner/LocalLandmarkExplorer/.pythonlibs/lib/python3.11/site-packages/redis/commands/core.py", line 1821, in get
    return self.execute_command("GET", name)
           ^^^^^^^^^^^^^^^^^^^^^^^^^^^^^^^^^
  File "/home/runner/LocalLandmarkExplorer/.pythonlibs/lib/python3.11/site-packages/redis/client.py", line 545, in execute_command
    conn = self.connection or pool.get_connection(command_name, **options)
                              ^^^^^^^^^^^^^^^^^^^^^^^^^^^^^^^^^^^^^^^^^^^^
  File "/home/runner/LocalLandmarkExplorer/.pythonlibs/lib/python3.11/site-packages/redis/connection.py", line 1074, in get_connection
    connection.connect()
  File "/home/runner/LocalLandmarkExplorer/.pythonlibs/lib/python3.11/site-packages/redis/connection.py", line 283, in connect
    raise ConnectionError(self._error_message(e))
redis.exceptions.ConnectionError: Error 99 connecting to localhost:6379. Cannot assign requested address.
INFO:werkzeug:172.31.196.123 - - [23/Sep/2024 15:36:43] "GET /get_landmarks?search=&specific=false&north=59.285876827885154&south=59.23323003490944&east=15.265331268310549&west=15.160961151123047 HTTP/1.1" 500 -